[2025-03-26 20:30:33,053] ERROR log_exception() L1449 Exception on /produto [PUT] - call_trace=/home/takimoto/sample_FullStack/env_dev/lib/python3.12/site-packages/flask/app.py L1449
Traceback (most recent call last):
  File "/home/takimoto/sample_FullStack/env_dev/lib/python3.12/site-packages/flask/app.py", line 2073, in wsgi_app
    response = self.full_dispatch_request()
               ^^^^^^^^^^^^^^^^^^^^^^^^^^^^
  File "/home/takimoto/sample_FullStack/env_dev/lib/python3.12/site-packages/flask/app.py", line 1519, in full_dispatch_request
    rv = self.handle_user_exception(e)
         ^^^^^^^^^^^^^^^^^^^^^^^^^^^^^
  File "/home/takimoto/sample_FullStack/env_dev/lib/python3.12/site-packages/flask_cors/extension.py", line 165, in wrapped_function
    return cors_after_request(app.make_response(f(*args, **kwargs)))
                                                ^^^^^^^^^^^^^^^^^^
  File "/home/takimoto/sample_FullStack/env_dev/lib/python3.12/site-packages/flask/app.py", line 1517, in full_dispatch_request
    rv = self.dispatch_request()
         ^^^^^^^^^^^^^^^^^^^^^^^
  File "/home/takimoto/sample_FullStack/env_dev/lib/python3.12/site-packages/flask/app.py", line 1503, in dispatch_request
    return self.ensure_sync(self.view_functions[rule.endpoint])(**req.view_args)
           ^^^^^^^^^^^^^^^^^^^^^^^^^^^^^^^^^^^^^^^^^^^^^^^^^^^^^^^^^^^^^^^^^^^^^
  File "/home/takimoto/sample_FullStack/env_dev/lib/python3.12/site-packages/flask_openapi3/scaffold.py", line 273, in wrapper
    resp = _do_wrapper(
           ^^^^^^^^^^^^
  File "/home/takimoto/sample_FullStack/env_dev/lib/python3.12/site-packages/flask_openapi3/do_wrapper.py", line 135, in _do_wrapper
    response = func(**request_kwargs)
               ^^^^^^^^^^^^^^^^^^^^^^
  File "/home/takimoto/sample_FullStack/desenvolvimento-full-stack-main/desenvolvimento-full-stack-basico/aula-3/meu_app_api/app.py", line 130, in update_produto
    produto = session.query(Produto).filter(Produto.nome == produto_nome).first()
                                                            ^^^^^^^^^^^^
NameError: name 'produto_nome' is not defined. Did you mean: 'produto_tag'?
[2025-03-26 20:30:33,059] INFO _log() L225  127.0.0.1 - - [26/Mar/2025 20:30:33] "[35m[1mPUT /produto HTTP/1.1[0m" 500 - - call_trace=/home/takimoto/sample_FullStack/env_dev/lib/python3.12/site-packages/werkzeug/_internal.py L225 
[2025-03-26 20:31:12,632] INFO _log() L225   * Detected change in '/home/takimoto/sample_FullStack/desenvolvimento-full-stack-main/desenvolvimento-full-stack-basico/aula-3/meu_app_api/app.py', reloading - call_trace=/home/takimoto/sample_FullStack/env_dev/lib/python3.12/site-packages/werkzeug/_internal.py L225 
[2025-03-26 20:31:50,243] INFO _log() L225  127.0.0.1 - - [26/Mar/2025 20:31:50] "PUT /produto HTTP/1.1" 200 - - call_trace=/home/takimoto/sample_FullStack/env_dev/lib/python3.12/site-packages/werkzeug/_internal.py L225 
